[2023-10-21T09:55:55.670+0000] {taskinstance.py:1159} INFO - Dependencies all met for dep_context=non-requeueable deps ti=<TaskInstance: postgres_db_dag.es_create_index scheduled__2023-10-21T09:54:47.057944+00:00 [queued]>
[2023-10-21T09:55:55.678+0000] {taskinstance.py:1159} INFO - Dependencies all met for dep_context=requeueable deps ti=<TaskInstance: postgres_db_dag.es_create_index scheduled__2023-10-21T09:54:47.057944+00:00 [queued]>
[2023-10-21T09:55:55.678+0000] {taskinstance.py:1361} INFO - Starting attempt 1 of 1
[2023-10-21T09:55:55.689+0000] {taskinstance.py:1382} INFO - Executing <Task(PythonOperator): es_create_index> on 2023-10-21 09:54:47.057944+00:00
[2023-10-21T09:55:55.699+0000] {standard_task_runner.py:57} INFO - Started process 76490 to run task
[2023-10-21T09:55:55.704+0000] {standard_task_runner.py:84} INFO - Running: ['***', 'tasks', 'run', 'postgres_db_dag', 'es_create_index', 'scheduled__2023-10-21T09:54:47.057944+00:00', '--job-id', '11215', '--raw', '--subdir', 'DAGS_FOLDER/test_movie_etl.py', '--cfg-path', '/tmp/tmpejicaiog']
[2023-10-21T09:55:55.713+0000] {standard_task_runner.py:85} INFO - Job 11215: Subtask es_create_index
[2023-10-21T09:55:55.863+0000] {task_command.py:416} INFO - Running <TaskInstance: postgres_db_dag.es_create_index scheduled__2023-10-21T09:54:47.057944+00:00 [running]> on host 4b99fd46be77
[2023-10-21T09:55:56.044+0000] {taskinstance.py:1662} INFO - Exporting env vars: AIRFLOW_CTX_DAG_OWNER='***' AIRFLOW_CTX_DAG_ID='postgres_db_dag' AIRFLOW_CTX_TASK_ID='es_create_index' AIRFLOW_CTX_EXECUTION_DATE='2023-10-21T09:54:47.057944+00:00' AIRFLOW_CTX_TRY_NUMBER='1' AIRFLOW_CTX_DAG_RUN_ID='scheduled__2023-10-21T09:54:47.057944+00:00'
[2023-10-21T09:55:56.657+0000] {_transport.py:358} INFO - PUT http://elasticsearch:9200/movies [status:N/A duration:0.008s]
[2023-10-21T09:55:56.658+0000] {_node_pool.py:249} WARNING - Node <Urllib3HttpNode(http://elasticsearch:9200)> has failed for 1 times in a row, putting on 1 second timeout
[2023-10-21T09:55:56.658+0000] {_transport.py:395} WARNING - Retrying request after failure (attempt 0 of 3)
Traceback (most recent call last):
  File "/home/airflow/.local/lib/python3.8/site-packages/elastic_transport/_transport.py", line 328, in perform_request
    meta, raw_data = node.perform_request(
  File "/home/airflow/.local/lib/python3.8/site-packages/elastic_transport/_node/_http_urllib3.py", line 197, in perform_request
    raise err from None
elastic_transport.ConnectionError: Connection error caused by: NewConnectionError(<urllib3.connection.HTTPConnection object at 0xffff5c0931c0>: Failed to establish a new connection: [Errno -2] Name or service not known)
[2023-10-21T09:55:56.670+0000] {_transport.py:358} INFO - PUT http://elasticsearch:9200/movies [status:N/A duration:0.005s]
[2023-10-21T09:55:56.670+0000] {_node_pool.py:249} WARNING - Node <Urllib3HttpNode(http://elasticsearch:9200)> has failed for 2 times in a row, putting on 2 second timeout
[2023-10-21T09:55:56.670+0000] {_transport.py:395} WARNING - Retrying request after failure (attempt 1 of 3)
Traceback (most recent call last):
  File "/home/airflow/.local/lib/python3.8/site-packages/elastic_transport/_transport.py", line 328, in perform_request
    meta, raw_data = node.perform_request(
  File "/home/airflow/.local/lib/python3.8/site-packages/elastic_transport/_node/_http_urllib3.py", line 197, in perform_request
    raise err from None
elastic_transport.ConnectionError: Connection error caused by: NewConnectionError(<urllib3.connection.HTTPConnection object at 0xffff5c093460>: Failed to establish a new connection: [Errno -2] Name or service not known)
[2023-10-21T09:55:56.676+0000] {_transport.py:358} INFO - PUT http://elasticsearch:9200/movies [status:N/A duration:0.005s]
[2023-10-21T09:55:56.676+0000] {_node_pool.py:249} WARNING - Node <Urllib3HttpNode(http://elasticsearch:9200)> has failed for 3 times in a row, putting on 4 second timeout
[2023-10-21T09:55:56.676+0000] {_transport.py:395} WARNING - Retrying request after failure (attempt 2 of 3)
Traceback (most recent call last):
  File "/home/airflow/.local/lib/python3.8/site-packages/elastic_transport/_transport.py", line 328, in perform_request
    meta, raw_data = node.perform_request(
  File "/home/airflow/.local/lib/python3.8/site-packages/elastic_transport/_node/_http_urllib3.py", line 197, in perform_request
    raise err from None
elastic_transport.ConnectionError: Connection error caused by: NewConnectionError(<urllib3.connection.HTTPConnection object at 0xffff5c093520>: Failed to establish a new connection: [Errno -2] Name or service not known)
[2023-10-21T09:55:56.682+0000] {_transport.py:358} INFO - PUT http://elasticsearch:9200/movies [status:N/A duration:0.005s]
[2023-10-21T09:55:56.682+0000] {_node_pool.py:249} WARNING - Node <Urllib3HttpNode(http://elasticsearch:9200)> has failed for 4 times in a row, putting on 8 second timeout
[2023-10-21T09:55:56.682+0000] {taskinstance.py:1937} ERROR - Task failed with exception
Traceback (most recent call last):
  File "/home/airflow/.local/lib/python3.8/site-packages/airflow/operators/python.py", line 192, in execute
    return_value = self.execute_callable()
  File "/home/airflow/.local/lib/python3.8/site-packages/airflow/operators/python.py", line 209, in execute_callable
    return self.python_callable(*self.op_args, **self.op_kwargs)
  File "/opt/airflow/dags/test_movie_etl.py", line 190, in es_create_index
    response = elastic.indices.create(index='movies', body=MAPPING_MOVIES, ignore=400)
  File "/home/airflow/.local/lib/python3.8/site-packages/elasticsearch/_sync/client/utils.py", line 414, in wrapped
    return api(*args, **kwargs)
  File "/home/airflow/.local/lib/python3.8/site-packages/elasticsearch/_sync/client/indices.py", line 547, in create
    return self.perform_request(  # type: ignore[return-value]
  File "/home/airflow/.local/lib/python3.8/site-packages/elasticsearch/_sync/client/_base.py", line 389, in perform_request
    return self._client.perform_request(
  File "/home/airflow/.local/lib/python3.8/site-packages/elasticsearch/_sync/client/_base.py", line 285, in perform_request
    meta, resp_body = self.transport.perform_request(
  File "/home/airflow/.local/lib/python3.8/site-packages/elastic_transport/_transport.py", line 328, in perform_request
    meta, raw_data = node.perform_request(
  File "/home/airflow/.local/lib/python3.8/site-packages/elastic_transport/_node/_http_urllib3.py", line 197, in perform_request
    raise err from None
elastic_transport.ConnectionError: Connection error caused by: ConnectionError(Connection error caused by: NewConnectionError(<urllib3.connection.HTTPConnection object at 0xffff5c0931c0>: Failed to establish a new connection: [Errno -2] Name or service not known))
[2023-10-21T09:55:56.694+0000] {taskinstance.py:1400} INFO - Marking task as FAILED. dag_id=postgres_db_dag, task_id=es_create_index, execution_date=20231021T095447, start_date=20231021T095555, end_date=20231021T095556
[2023-10-21T09:55:56.706+0000] {standard_task_runner.py:104} ERROR - Failed to execute job 11215 for task es_create_index (Connection error caused by: ConnectionError(Connection error caused by: NewConnectionError(<urllib3.connection.HTTPConnection object at 0xffff5c0931c0>: Failed to establish a new connection: [Errno -2] Name or service not known)); 76490)
[2023-10-21T09:55:56.745+0000] {local_task_job_runner.py:228} INFO - Task exited with return code 1
[2023-10-21T09:55:56.773+0000] {taskinstance.py:2778} INFO - 0 downstream tasks scheduled from follow-on schedule check
