[2023-10-21T13:26:29.201+0000] {taskinstance.py:1159} INFO - Dependencies all met for dep_context=non-requeueable deps ti=<TaskInstance: cinema_ETL.fetch_changed_genres_movies_ids scheduled__2023-10-21T13:25:01.235699+00:00 [queued]>
[2023-10-21T13:26:29.210+0000] {taskinstance.py:1159} INFO - Dependencies all met for dep_context=requeueable deps ti=<TaskInstance: cinema_ETL.fetch_changed_genres_movies_ids scheduled__2023-10-21T13:25:01.235699+00:00 [queued]>
[2023-10-21T13:26:29.211+0000] {taskinstance.py:1361} INFO - Starting attempt 1 of 1
[2023-10-21T13:26:29.226+0000] {taskinstance.py:1382} INFO - Executing <Task(PythonOperator): fetch_changed_genres_movies_ids> on 2023-10-21 13:25:01.235699+00:00
[2023-10-21T13:26:29.236+0000] {standard_task_runner.py:57} INFO - Started process 3211 to run task
[2023-10-21T13:26:29.246+0000] {standard_task_runner.py:84} INFO - Running: ['***', 'tasks', 'run', 'cinema_ETL', 'fetch_changed_genres_movies_ids', 'scheduled__2023-10-21T13:25:01.235699+00:00', '--job-id', '17', '--raw', '--subdir', 'DAGS_FOLDER/test_movie_etl.py', '--cfg-path', '/tmp/tmpqc49m9w2']
[2023-10-21T13:26:29.253+0000] {standard_task_runner.py:85} INFO - Job 17: Subtask fetch_changed_genres_movies_ids
[2023-10-21T13:26:29.462+0000] {task_command.py:416} INFO - Running <TaskInstance: cinema_ETL.fetch_changed_genres_movies_ids scheduled__2023-10-21T13:25:01.235699+00:00 [running]> on host 9f6b2b4cbb27
[2023-10-21T13:26:29.751+0000] {taskinstance.py:1662} INFO - Exporting env vars: AIRFLOW_CTX_DAG_OWNER='***' AIRFLOW_CTX_DAG_ID='cinema_ETL' AIRFLOW_CTX_TASK_ID='fetch_changed_genres_movies_ids' AIRFLOW_CTX_EXECUTION_DATE='2023-10-21T13:25:01.235699+00:00' AIRFLOW_CTX_TRY_NUMBER='1' AIRFLOW_CTX_DAG_RUN_ID='scheduled__2023-10-21T13:25:01.235699+00:00'
[2023-10-21T13:26:29.810+0000] {taskinstance.py:1937} ERROR - Task failed with exception
Traceback (most recent call last):
  File "/home/airflow/.local/lib/python3.8/site-packages/airflow/operators/python.py", line 192, in execute
    return_value = self.execute_callable()
  File "/home/airflow/.local/lib/python3.8/site-packages/airflow/operators/python.py", line 209, in execute_callable
    return self.python_callable(*self.op_args, **self.op_kwargs)
  File "/opt/airflow/dags/test_movie_etl.py", line 52, in fetch_changed_genres_movies_ids
    pg_conn = pg_hook.get_conn()
  File "/home/airflow/.local/lib/python3.8/site-packages/airflow/providers/postgres/hooks/postgres.py", line 125, in get_conn
    conn = deepcopy(self.connection or self.get_connection(conn_id))
  File "/home/airflow/.local/lib/python3.8/site-packages/airflow/hooks/base.py", line 72, in get_connection
    conn = Connection.get_connection_from_secrets(conn_id)
  File "/home/airflow/.local/lib/python3.8/site-packages/airflow/models/connection.py", line 477, in get_connection_from_secrets
    raise AirflowNotFoundException(f"The conn_id `{conn_id}` isn't defined")
airflow.exceptions.AirflowNotFoundException: The conn_id `postgres_db` isn't defined
[2023-10-21T13:26:29.841+0000] {taskinstance.py:1400} INFO - Marking task as FAILED. dag_id=cinema_ETL, task_id=fetch_changed_genres_movies_ids, execution_date=20231021T132501, start_date=20231021T132629, end_date=20231021T132629
[2023-10-21T13:26:29.859+0000] {standard_task_runner.py:104} ERROR - Failed to execute job 17 for task fetch_changed_genres_movies_ids (The conn_id `postgres_db` isn't defined; 3211)
[2023-10-21T13:26:29.881+0000] {local_task_job_runner.py:228} INFO - Task exited with return code 1
[2023-10-21T13:26:29.938+0000] {taskinstance.py:2778} INFO - 0 downstream tasks scheduled from follow-on schedule check
