[2023-10-20T01:12:31.527+0000] {taskinstance.py:1159} INFO - Dependencies all met for dep_context=non-requeueable deps ti=<TaskInstance: postgres_db_dag.es_create_index scheduled__2023-10-20T01:11:27.064362+00:00 [queued]>
[2023-10-20T01:12:31.532+0000] {taskinstance.py:1159} INFO - Dependencies all met for dep_context=requeueable deps ti=<TaskInstance: postgres_db_dag.es_create_index scheduled__2023-10-20T01:11:27.064362+00:00 [queued]>
[2023-10-20T01:12:31.533+0000] {taskinstance.py:1361} INFO - Starting attempt 1 of 1
[2023-10-20T01:12:31.541+0000] {taskinstance.py:1382} INFO - Executing <Task(PythonOperator): es_create_index> on 2023-10-20 01:11:27.064362+00:00
[2023-10-20T01:12:31.546+0000] {standard_task_runner.py:57} INFO - Started process 23015 to run task
[2023-10-20T01:12:31.550+0000] {standard_task_runner.py:84} INFO - Running: ['***', 'tasks', 'run', 'postgres_db_dag', 'es_create_index', 'scheduled__2023-10-20T01:11:27.064362+00:00', '--job-id', '3363', '--raw', '--subdir', 'DAGS_FOLDER/test_movie_etl.py', '--cfg-path', '/tmp/tmplh6_nwsf']
[2023-10-20T01:12:31.555+0000] {standard_task_runner.py:85} INFO - Job 3363: Subtask es_create_index
[2023-10-20T01:12:31.644+0000] {task_command.py:416} INFO - Running <TaskInstance: postgres_db_dag.es_create_index scheduled__2023-10-20T01:11:27.064362+00:00 [running]> on host 4b99fd46be77
[2023-10-20T01:12:31.736+0000] {taskinstance.py:1662} INFO - Exporting env vars: AIRFLOW_CTX_DAG_OWNER='***' AIRFLOW_CTX_DAG_ID='postgres_db_dag' AIRFLOW_CTX_TASK_ID='es_create_index' AIRFLOW_CTX_EXECUTION_DATE='2023-10-20T01:11:27.064362+00:00' AIRFLOW_CTX_TRY_NUMBER='1' AIRFLOW_CTX_DAG_RUN_ID='scheduled__2023-10-20T01:11:27.064362+00:00'
[2023-10-20T01:12:32.130+0000] {_transport.py:358} INFO - PUT http://elasticsearch:9200/movies [status:N/A duration:0.007s]
[2023-10-20T01:12:32.130+0000] {_node_pool.py:249} WARNING - Node <Urllib3HttpNode(http://elasticsearch:9200)> has failed for 1 times in a row, putting on 1 second timeout
[2023-10-20T01:12:32.130+0000] {_transport.py:395} WARNING - Retrying request after failure (attempt 0 of 3)
Traceback (most recent call last):
  File "/home/airflow/.local/lib/python3.8/site-packages/elastic_transport/_transport.py", line 328, in perform_request
    meta, raw_data = node.perform_request(
  File "/home/airflow/.local/lib/python3.8/site-packages/elastic_transport/_node/_http_urllib3.py", line 197, in perform_request
    raise err from None
elastic_transport.ConnectionError: Connection error caused by: NewConnectionError(<urllib3.connection.HTTPConnection object at 0xffff5c0fa610>: Failed to establish a new connection: [Errno -2] Name or service not known)
[2023-10-20T01:12:32.139+0000] {_transport.py:358} INFO - PUT http://elasticsearch:9200/movies [status:N/A duration:0.004s]
[2023-10-20T01:12:32.139+0000] {_node_pool.py:249} WARNING - Node <Urllib3HttpNode(http://elasticsearch:9200)> has failed for 2 times in a row, putting on 2 second timeout
[2023-10-20T01:12:32.139+0000] {_transport.py:395} WARNING - Retrying request after failure (attempt 1 of 3)
Traceback (most recent call last):
  File "/home/airflow/.local/lib/python3.8/site-packages/elastic_transport/_transport.py", line 328, in perform_request
    meta, raw_data = node.perform_request(
  File "/home/airflow/.local/lib/python3.8/site-packages/elastic_transport/_node/_http_urllib3.py", line 197, in perform_request
    raise err from None
elastic_transport.ConnectionError: Connection error caused by: NewConnectionError(<urllib3.connection.HTTPConnection object at 0xffff5c0fa8b0>: Failed to establish a new connection: [Errno -2] Name or service not known)
[2023-10-20T01:12:32.143+0000] {_transport.py:358} INFO - PUT http://elasticsearch:9200/movies [status:N/A duration:0.004s]
[2023-10-20T01:12:32.144+0000] {_node_pool.py:249} WARNING - Node <Urllib3HttpNode(http://elasticsearch:9200)> has failed for 3 times in a row, putting on 4 second timeout
[2023-10-20T01:12:32.144+0000] {_transport.py:395} WARNING - Retrying request after failure (attempt 2 of 3)
Traceback (most recent call last):
  File "/home/airflow/.local/lib/python3.8/site-packages/elastic_transport/_transport.py", line 328, in perform_request
    meta, raw_data = node.perform_request(
  File "/home/airflow/.local/lib/python3.8/site-packages/elastic_transport/_node/_http_urllib3.py", line 197, in perform_request
    raise err from None
elastic_transport.ConnectionError: Connection error caused by: NewConnectionError(<urllib3.connection.HTTPConnection object at 0xffff5c0fa970>: Failed to establish a new connection: [Errno -2] Name or service not known)
[2023-10-20T01:12:32.148+0000] {_transport.py:358} INFO - PUT http://elasticsearch:9200/movies [status:N/A duration:0.004s]
[2023-10-20T01:12:32.148+0000] {_node_pool.py:249} WARNING - Node <Urllib3HttpNode(http://elasticsearch:9200)> has failed for 4 times in a row, putting on 8 second timeout
[2023-10-20T01:12:32.149+0000] {taskinstance.py:1937} ERROR - Task failed with exception
Traceback (most recent call last):
  File "/home/airflow/.local/lib/python3.8/site-packages/airflow/operators/python.py", line 192, in execute
    return_value = self.execute_callable()
  File "/home/airflow/.local/lib/python3.8/site-packages/airflow/operators/python.py", line 209, in execute_callable
    return self.python_callable(*self.op_args, **self.op_kwargs)
  File "/opt/airflow/dags/test_movie_etl.py", line 190, in es_create_index
    response = elastic.indices.create(index='movies', body=MAPPING_MOVIES, ignore=400)
  File "/home/airflow/.local/lib/python3.8/site-packages/elasticsearch/_sync/client/utils.py", line 414, in wrapped
    return api(*args, **kwargs)
  File "/home/airflow/.local/lib/python3.8/site-packages/elasticsearch/_sync/client/indices.py", line 547, in create
    return self.perform_request(  # type: ignore[return-value]
  File "/home/airflow/.local/lib/python3.8/site-packages/elasticsearch/_sync/client/_base.py", line 389, in perform_request
    return self._client.perform_request(
  File "/home/airflow/.local/lib/python3.8/site-packages/elasticsearch/_sync/client/_base.py", line 285, in perform_request
    meta, resp_body = self.transport.perform_request(
  File "/home/airflow/.local/lib/python3.8/site-packages/elastic_transport/_transport.py", line 328, in perform_request
    meta, raw_data = node.perform_request(
  File "/home/airflow/.local/lib/python3.8/site-packages/elastic_transport/_node/_http_urllib3.py", line 197, in perform_request
    raise err from None
elastic_transport.ConnectionError: Connection error caused by: ConnectionError(Connection error caused by: NewConnectionError(<urllib3.connection.HTTPConnection object at 0xffff5c0fa610>: Failed to establish a new connection: [Errno -2] Name or service not known))
[2023-10-20T01:12:32.157+0000] {taskinstance.py:1400} INFO - Marking task as FAILED. dag_id=postgres_db_dag, task_id=es_create_index, execution_date=20231020T011127, start_date=20231020T011231, end_date=20231020T011232
[2023-10-20T01:12:32.165+0000] {standard_task_runner.py:104} ERROR - Failed to execute job 3363 for task es_create_index (Connection error caused by: ConnectionError(Connection error caused by: NewConnectionError(<urllib3.connection.HTTPConnection object at 0xffff5c0fa610>: Failed to establish a new connection: [Errno -2] Name or service not known)); 23015)
[2023-10-20T01:12:32.208+0000] {local_task_job_runner.py:228} INFO - Task exited with return code 1
[2023-10-20T01:12:32.225+0000] {taskinstance.py:2778} INFO - 0 downstream tasks scheduled from follow-on schedule check
