[2023-10-19T11:29:23.583+0000] {taskinstance.py:1159} INFO - Dependencies all met for dep_context=non-requeueable deps ti=<TaskInstance: postgres_db_dag.es_create_index scheduled__2023-10-19T11:28:21.938957+00:00 [queued]>
[2023-10-19T11:29:23.588+0000] {taskinstance.py:1159} INFO - Dependencies all met for dep_context=requeueable deps ti=<TaskInstance: postgres_db_dag.es_create_index scheduled__2023-10-19T11:28:21.938957+00:00 [queued]>
[2023-10-19T11:29:23.589+0000] {taskinstance.py:1361} INFO - Starting attempt 1 of 1
[2023-10-19T11:29:23.596+0000] {taskinstance.py:1382} INFO - Executing <Task(PythonOperator): es_create_index> on 2023-10-19 11:28:21.938957+00:00
[2023-10-19T11:29:23.601+0000] {standard_task_runner.py:57} INFO - Started process 557 to run task
[2023-10-19T11:29:23.606+0000] {standard_task_runner.py:84} INFO - Running: ['***', 'tasks', 'run', 'postgres_db_dag', 'es_create_index', 'scheduled__2023-10-19T11:28:21.938957+00:00', '--job-id', '65', '--raw', '--subdir', 'DAGS_FOLDER/test_movie_etl.py', '--cfg-path', '/tmp/tmpkxqragly']
[2023-10-19T11:29:23.613+0000] {standard_task_runner.py:85} INFO - Job 65: Subtask es_create_index
[2023-10-19T11:29:23.678+0000] {task_command.py:416} INFO - Running <TaskInstance: postgres_db_dag.es_create_index scheduled__2023-10-19T11:28:21.938957+00:00 [running]> on host 4b99fd46be77
[2023-10-19T11:29:23.787+0000] {taskinstance.py:1662} INFO - Exporting env vars: AIRFLOW_CTX_DAG_OWNER='***' AIRFLOW_CTX_DAG_ID='postgres_db_dag' AIRFLOW_CTX_TASK_ID='es_create_index' AIRFLOW_CTX_EXECUTION_DATE='2023-10-19T11:28:21.938957+00:00' AIRFLOW_CTX_TRY_NUMBER='1' AIRFLOW_CTX_DAG_RUN_ID='scheduled__2023-10-19T11:28:21.938957+00:00'
[2023-10-19T11:29:24.149+0000] {_transport.py:335} INFO - PUT http://elasticsearch:9200/movies [status:400 duration:0.038s]
[2023-10-19T11:29:24.150+0000] {test_movie_etl.py:195} ERROR - Ошибка: [{'type': 'resource_already_exists_exception', 'reason': 'index [movies/YmS003wEQ5afFY0EKOTBhA] already exists', 'index_uuid': 'YmS003wEQ5afFY0EKOTBhA', 'index': 'movies'}]
[2023-10-19T11:29:24.150+0000] {test_movie_etl.py:196} INFO - {'error': {'root_cause': [{'type': 'resource_already_exists_exception', 'reason': 'index [movies/YmS003wEQ5afFY0EKOTBhA] already exists', 'index_uuid': 'YmS003wEQ5afFY0EKOTBhA', 'index': 'movies'}], 'type': 'resource_already_exists_exception', 'reason': 'index [movies/YmS003wEQ5afFY0EKOTBhA] already exists', 'index_uuid': 'YmS003wEQ5afFY0EKOTBhA', 'index': 'movies'}, 'status': 400}
[2023-10-19T11:29:24.151+0000] {python.py:194} INFO - Done. Returned value was: None
[2023-10-19T11:29:24.160+0000] {taskinstance.py:1400} INFO - Marking task as SUCCESS. dag_id=postgres_db_dag, task_id=es_create_index, execution_date=20231019T112821, start_date=20231019T112923, end_date=20231019T112924
[2023-10-19T11:29:24.185+0000] {local_task_job_runner.py:228} INFO - Task exited with return code 0
[2023-10-19T11:29:24.204+0000] {taskinstance.py:2778} INFO - 0 downstream tasks scheduled from follow-on schedule check
